<?xml version="1.0" ?>
<!-- =================================================================================== -->
<!-- |    This document was autogenerated by xacro from rb10_1300e.urdf.xacro          | -->
<!-- |    EDITING THIS FILE BY HAND IS NOT RECOMMENDED                                 | -->
<!-- =================================================================================== -->
<robot name="rb10_1300e">
  <link name="link0">
    <visual>
      <geometry>
        <mesh filename="package://rbpodo_description/meshes/rb10_1300e/visual/link0.dae"/>
      </geometry>
    </visual>
    <collision>
      <geometry>
        <mesh filename="package://rbpodo_description/meshes/rb10_1300e/collision/link0.stl"/>
      </geometry>
    </collision>
  </link>
  <link name="link1">
    <visual>
      <geometry>
        <mesh filename="package://rbpodo_description/meshes/rb10_1300e/visual/link1.dae"/>
      </geometry>
    </visual>
    <collision>
      <geometry>
        <mesh filename="package://rbpodo_description/meshes/rb10_1300e/collision/link1.stl"/>
      </geometry>
    </collision>
    <inertial>
      <origin rpy="0 0 0" xyz="0.000021 -0.007855 -0.042537"/>
      <mass value="8.366"/>
      <inertia ixx="0.027403652" ixy="-5.926e-06" ixz="-1.0119e-05" iyy="0.027770573" iyz="0.003030512" izz="0.026140211"/>
    </inertial>
  </link>
  <link name="link2">
    <visual>
      <geometry>
        <mesh filename="package://rbpodo_description/meshes/rb10_1300e/visual/link2.dae"/>
      </geometry>
    </visual>
    <collision>
      <geometry>
        <mesh filename="package://rbpodo_description/meshes/rb10_1300e/collision/link2.stl"/>
      </geometry>
    </collision>
    <inertial>
      <origin rpy="0 0 0" xyz="-0.000013 -0.155462 0.225241"/>
      <mass value="15.61"/>
      <inertia ixx="1.140650644" ixy="-1.3042e-05" ixz="-6.7084e-05" iyy="1.134398623" iyz="0.024507884" izz="0.050849068"/>
    </inertial>
  </link>
  <link name="link3">
    <visual>
      <geometry>
        <mesh filename="package://rbpodo_description/meshes/rb10_1300e/visual/link3.dae"/>
      </geometry>
    </visual>
    <collision>
      <geometry>
        <mesh filename="package://rbpodo_description/meshes/rb10_1300e/collision/link3.stl"/>
      </geometry>
    </collision>
    <inertial>
      <origin rpy="0 0 0" xyz="-0.000048 -0.013885 0.325013"/>
      <mass value="5.69"/>
      <inertia ixx="0.312033029" ixy="9.298e-06" ixz="1.169e-05" iyy="0.311287646" iyz="0.005331552" izz="0.011397824"/>
    </inertial>
  </link>
  <link name="link4">
    <visual>
      <geometry>
        <mesh filename="package://rbpodo_description/meshes/rb10_1300e/visual/link4.dae"/>
      </geometry>
    </visual>
    <collision>
      <geometry>
        <mesh filename="package://rbpodo_description/meshes/rb10_1300e/collision/link4.stl"/>
      </geometry>
    </collision>
    <inertial>
      <origin rpy="0 0 0" xyz="0.000093 -0.113949 0.026461"/>
      <mass value="2.062"/>
      <inertia ixx="0.0027111" ixy="-8.022e-06" ixz="1.1208e-05" iyy="0.002715407" iyz="0.000144243" izz="0.002157043"/>
    </inertial>
  </link>
  <link name="link5">
    <visual>
      <geometry>
        <mesh filename="package://rbpodo_description/meshes/rb10_1300e/visual/link5.dae"/>
      </geometry>
    </visual>
    <collision>
      <geometry>
        <mesh filename="package://rbpodo_description/meshes/rb10_1300e/collision/link5.stl"/>
      </geometry>
    </collision>
    <inertial>
      <origin rpy="0 0 0" xyz="-0.000093 -0.026434 -0.003233"/>
      <mass value="2.061"/>
      <inertia ixx="0.002706437" ixy="1.1205e-05" ixz="-8.016e-06" iyy="0.002153592" iyz="0.000141528" izz="0.002712272"/>
    </inertial>
  </link>
  <link name="link6">
    <visual>
      <geometry>
        <mesh filename="package://rbpodo_description/meshes/rb10_1300e/visual/link6.dae"/>
      </geometry>
    </visual>
    <collision>
      <geometry>
        <mesh filename="package://rbpodo_description/meshes/rb10_1300e/collision/link6.stl"/>
      </geometry>
    </collision>
    <inertial>
      <origin rpy="0 0 0" xyz="-0.000210 -0.092540 -0.000292"/>
      <mass value="0.406"/>
      <inertia ixx="0.000345314" ixy="5.73e-07" ixz="6.61e-07" iyy="0.000532873" iyz="-5.4e-08" izz="0.000340021"/>
    </inertial>
  </link>
  <link name="tcp"/>
  <joint name="base" type="revolute">
    <origin rpy="0 0 0" xyz="0 0 0"/>
    <parent link="link0"/>
    <child link="link1"/>
    <axis xyz="0 0 1"/>
    <limit effort="10" lower="-3.14" upper="3.14" velocity="3.14"/>
  </joint>
  <joint name="shoulder" type="revolute">
    <origin rpy="0 0 0" xyz="0 0 0.197"/>
    <parent link="link1"/>
    <child link="link2"/>
    <axis xyz="0 1 0"/>
    <limit effort="10" lower="-3.14" upper="3.14" velocity="3.14"/>
  </joint>
  <joint name="elbow" type="revolute">
    <origin rpy="0 0 0" xyz="0 -0.1875 0.6127"/>
    <parent link="link2"/>
    <child link="link3"/>
    <axis xyz="0 1 0"/>
    <limit effort="10" lower="-3.14" upper="3.14" velocity="3.14"/>
  </joint>
  <joint name="wrist1" type="revolute">
    <origin rpy="0 0 0" xyz="0 0.1484 0.57015"/>
    <parent link="link3"/>
    <child link="link4"/>
    <axis xyz="0 1 0"/>
    <limit effort="10" lower="-3.14" upper="3.14" velocity="3.14"/>
  </joint>
  <joint name="wrist2" type="revolute">
    <origin rpy="0 0 0" xyz="0 -0.11715 0"/>
    <parent link="link4"/>
    <child link="link5"/>
    <axis xyz="0 0 1"/>
    <limit effort="10" lower="-3.14" upper="3.14" velocity="3.14"/>
  </joint>
  <joint name="wrist3" type="revolute">
    <origin rpy="0 0 0" xyz="0 0 0.11715"/>
    <parent link="link5"/>
    <child link="link6"/>
    <axis xyz="0 1 0"/>
    <limit effort="10" lower="-3.14" upper="3.14" velocity="3.14"/>
  </joint>
  <joint name="tcp_joint" type="fixed">
    <origin rpy="0 0 0" xyz="0 -0.1153 0"/>
    <parent link="link6"/>
    <child link="tcp"/>
  </joint>
  <ros2_control name="RBPodoHardwareInterface" type="system">
    <hardware>
      <plugin>mock_components/GenericSystem</plugin>
      <param name="mock_sensor_commands">False</param>
      <param name="state_following_offset">0.0</param>
    </hardware>
    <joint name="base">
      <param name="initial_position">0.0</param>
      <param name="torque_constant">1</param>
      <command_interface name="effort"/>
      <command_interface name="velocity"/>
      <command_interface name="position"/>
      <state_interface name="position"/>
      <state_interface name="effort"/>
    </joint>
    <joint name="shoulder">
      <param name="initial_position">0.0</param>
      <param name="torque_constant">1</param>
      <command_interface name="effort"/>
      <command_interface name="velocity"/>
      <command_interface name="position"/>
      <state_interface name="position"/>
      <state_interface name="effort"/>
    </joint>
    <joint name="elbow">
      <param name="initial_position">0.0</param>
      <param name="torque_constant">1</param>
      <command_interface name="effort"/>
      <command_interface name="velocity"/>
      <command_interface name="position"/>
      <state_interface name="position"/>
      <state_interface name="effort"/>
    </joint>
    <joint name="wrist1">
      <param name="initial_position">0.0</param>
      <param name="torque_constant">1</param>
      <command_interface name="effort"/>
      <command_interface name="velocity"/>
      <command_interface name="position"/>
      <state_interface name="position"/>
      <state_interface name="effort"/>
    </joint>
    <joint name="wrist2">
      <param name="initial_position">0.0</param>
      <param name="torque_constant">1</param>
      <command_interface name="effort"/>
      <command_interface name="velocity"/>
      <command_interface name="position"/>
      <state_interface name="position"/>
      <state_interface name="effort"/>
    </joint>
    <joint name="wrist3">
      <param name="initial_position">0.0</param>
      <param name="torque_constant">1</param>
      <command_interface name="effort"/>
      <command_interface name="velocity"/>
      <command_interface name="position"/>
      <state_interface name="position"/>
      <state_interface name="effort"/>
    </joint>
  </ros2_control>
</robot>
