<?xml version="1.0" ?>
<!-- =================================================================================== -->
<!-- |    This document was autogenerated by xacro from rb16_900e_u.urdf.xacro         | -->
<!-- |    EDITING THIS FILE BY HAND IS NOT RECOMMENDED                                 | -->
<!-- =================================================================================== -->
<robot name="rb16_900e_u">
  <link name="link0">
    <visual>
      <geometry>
        <mesh filename="package://rbpodo_description/meshes/rb16_900e_u/visual/link0.dae"/>
      </geometry>
    </visual>
    <collision>
      <geometry>
        <mesh filename="package://rbpodo_description/meshes/rb16_900e_u/collision/link0.stl"/>
      </geometry>
    </collision>
  </link>
  <link name="link1">
    <visual>
      <geometry>
        <mesh filename="package://rbpodo_description/meshes/rb16_900e_u/visual/link1.dae"/>
      </geometry>
    </visual>
    <collision>
      <geometry>
        <mesh filename="package://rbpodo_description/meshes/rb16_900e_u/collision/link1.stl"/>
      </geometry>
    </collision>
    <inertial>
      <origin rpy="0 0 0" xyz="0.00002146 -0.00785669 -0.04254277"/>
      <mass value="8.36480574"/>
      <inertia ixx="0.027396" ixy="-5.93e-06" ixz="-1.012e-05" iyy="0.02776248" iyz="0.00302947" izz="0.02613526"/>
    </inertial>
  </link>
  <link name="link2">
    <visual>
      <geometry>
        <mesh filename="package://rbpodo_description/meshes/rb16_900e_u/visual/link2.dae"/>
      </geometry>
    </visual>
    <collision>
      <geometry>
        <mesh filename="package://rbpodo_description/meshes/rb16_900e_u/collision/link2.stl"/>
      </geometry>
    </collision>
    <inertial>
      <origin rpy="0 0 0" xyz="-0.00001365 -0.15336597 0.14954192"/>
      <mass value="14.65108225"/>
      <inertia ixx="0.50968149" ixy="-1.346e-05" ixz="-5.604e-05" iyy="0.50447767" iyz="0.01549891" izz="0.0467351"/>
    </inertial>
  </link>
  <link name="link3">
    <visual>
      <geometry>
        <mesh filename="package://rbpodo_description/meshes/rb16_900e_u/visual/link3.dae"/>
      </geometry>
    </visual>
    <collision>
      <geometry>
        <mesh filename="package://rbpodo_description/meshes/rb16_900e_u/collision/link3.stl"/>
      </geometry>
    </collision>
    <inertial>
      <origin rpy="0 0 0" xyz="-0.00005454 0.13556427 0.21690278"/>
      <mass value="4.99600074"/>
      <inertia ixx="0.1196272" ixy="9.83e-06" ixz="2.67e-06" iyy="0.1190238" iyz="0.00299228" izz="0.00997462"/>
    </inertial>
  </link>
  <link name="link4">
    <visual>
      <geometry>
        <mesh filename="package://rbpodo_description/meshes/rb16_900e_u/visual/link4.dae"/>
      </geometry>
    </visual>
    <collision>
      <geometry>
        <mesh filename="package://rbpodo_description/meshes/rb16_900e_u/collision/link4.stl"/>
      </geometry>
    </collision>
    <inertial>
      <origin rpy="0 0 0" xyz="0.00009393 -0.11397578 0.02631456"/>
      <mass value="2.04897826"/>
      <inertia ixx="0.00268283" ixy="-8.03e-06" ixz="1.118e-05" iyy="0.00268757" iyz="0.0001404" izz="0.00213209"/>
    </inertial>
  </link>
  <link name="link5">
    <visual>
      <geometry>
        <mesh filename="package://rbpodo_description/meshes/rb16_900e_u/visual/link5.dae"/>
      </geometry>
    </visual>
    <collision>
      <geometry>
        <mesh filename="package://rbpodo_description/meshes/rb16_900e_u/collision/link5.stl"/>
      </geometry>
    </collision>
    <inertial>
      <origin rpy="0 0 0" xyz="-0.00009382 -0.02633944 0.11394822"/>
      <mass value="2.05100562"/>
      <inertia ixx="0.00268465" ixy="1.119e-05" ixz="-8.02e-06" iyy="0.00213501" iyz="0.00013799" izz="0.00269084"/>
    </inertial>
  </link>
  <link name="link6">
    <visual>
      <geometry>
        <mesh filename="package://rbpodo_description/meshes/rb16_900e_u/visual/link6.dae"/>
      </geometry>
    </visual>
    <collision>
      <geometry>
        <mesh filename="package://rbpodo_description/meshes/rb16_900e_u/collision/link6.stl"/>
      </geometry>
    </collision>
    <inertial>
      <origin rpy="0 0 0" xyz="-0.00020973 -0.09253967 -0.00029237"/>
      <mass value="0.40590103"/>
      <inertia ixx="0.00034531" ixy="5.7e-07" ixz="6.6e-07" iyy="0.00053287" iyz="-5e-08" izz="0.00034002"/>
    </inertial>
  </link>
  <link name="tcp"/>
  <joint name="base" type="revolute">
    <origin rpy="0 0 0" xyz="0 0 0.197"/>
    <parent link="link0"/>
    <child link="link1"/>
    <axis xyz="0 0 1"/>
    <limit effort="10" lower="-3.14" upper="3.14" velocity="3.14"/>
  </joint>
  <joint name="shoulder" type="revolute">
    <origin rpy="0 0 0" xyz="0 -0.1875 0"/>
    <parent link="link1"/>
    <child link="link2"/>
    <axis xyz="0 1 0"/>
    <limit effort="10" lower="-3.14" upper="3.14" velocity="3.14"/>
  </joint>
  <joint name="elbow" type="revolute">
    <origin rpy="0 0 0" xyz="0 0 0.4127"/>
    <parent link="link2"/>
    <child link="link3"/>
    <axis xyz="0 1 0"/>
    <limit effort="10" lower="-3.14" upper="3.14" velocity="3.14"/>
  </joint>
  <joint name="wrist1" type="revolute">
    <origin rpy="0 0 0" xyz="0 0.1514 0.37015"/>
    <parent link="link3"/>
    <child link="link4"/>
    <axis xyz="0 1 0"/>
    <limit effort="10" lower="-3.14" upper="3.14" velocity="3.14"/>
  </joint>
  <joint name="wrist2" type="revolute">
    <origin rpy="0 0 0" xyz="0 -0.11715 0"/>
    <parent link="link4"/>
    <child link="link5"/>
    <axis xyz="0 0 1"/>
    <limit effort="10" lower="-3.14" upper="3.14" velocity="3.14"/>
  </joint>
  <joint name="wrist3" type="revolute">
    <origin rpy="0 0 0" xyz="0 0 0.11715"/>
    <parent link="link5"/>
    <child link="link6"/>
    <axis xyz="0 1 0"/>
    <limit effort="10" lower="-3.14" upper="3.14" velocity="3.14"/>
  </joint>
  <joint name="tcp_joint" type="fixed">
    <origin rpy="0 0 0" xyz="0 -0.1153 0"/>
    <parent link="link6"/>
    <child link="tcp"/>
  </joint>
  <ros2_control name="RBPodoHardwareInterface" type="system">
    <hardware>
      <plugin>mock_components/GenericSystem</plugin>
      <param name="mock_sensor_commands">False</param>
      <param name="state_following_offset">0.0</param>
    </hardware>
    <joint name="base">
      <param name="initial_position">0.0</param>
      <param name="torque_constant">1</param>
      <command_interface name="effort"/>
      <command_interface name="velocity"/>
      <command_interface name="position"/>
      <state_interface name="position"/>
      <state_interface name="effort"/>
    </joint>
    <joint name="shoulder">
      <param name="initial_position">0.0</param>
      <param name="torque_constant">1</param>
      <command_interface name="effort"/>
      <command_interface name="velocity"/>
      <command_interface name="position"/>
      <state_interface name="position"/>
      <state_interface name="effort"/>
    </joint>
    <joint name="elbow">
      <param name="initial_position">0.0</param>
      <param name="torque_constant">1</param>
      <command_interface name="effort"/>
      <command_interface name="velocity"/>
      <command_interface name="position"/>
      <state_interface name="position"/>
      <state_interface name="effort"/>
    </joint>
    <joint name="wrist1">
      <param name="initial_position">0.0</param>
      <param name="torque_constant">1</param>
      <command_interface name="effort"/>
      <command_interface name="velocity"/>
      <command_interface name="position"/>
      <state_interface name="position"/>
      <state_interface name="effort"/>
    </joint>
    <joint name="wrist2">
      <param name="initial_position">0.0</param>
      <param name="torque_constant">1</param>
      <command_interface name="effort"/>
      <command_interface name="velocity"/>
      <command_interface name="position"/>
      <state_interface name="position"/>
      <state_interface name="effort"/>
    </joint>
    <joint name="wrist3">
      <param name="initial_position">0.0</param>
      <param name="torque_constant">1</param>
      <command_interface name="effort"/>
      <command_interface name="velocity"/>
      <command_interface name="position"/>
      <state_interface name="position"/>
      <state_interface name="effort"/>
    </joint>
  </ros2_control>
</robot>
