<?xml version="1.0" ?>
<!-- =================================================================================== -->
<!-- |    This document was autogenerated by xacro from rb3_730es_u.urdf.xacro         | -->
<!-- |    EDITING THIS FILE BY HAND IS NOT RECOMMENDED                                 | -->
<!-- =================================================================================== -->
<robot name="rb3_730es_u">
  <link name="link0">
    <visual>
      <geometry>
        <mesh filename="package://rbpodo_description/meshes/rb3_730es_u/visual/link0.dae"/>
      </geometry>
    </visual>
    <collision>
      <geometry>
        <mesh filename="package://rbpodo_description/meshes/rb3_730es_u/collision/link0.stl"/>
      </geometry>
    </collision>
  </link>
  <link name="link1">
    <visual>
      <geometry>
        <mesh filename="package://rbpodo_description/meshes/rb3_730es_u/visual/link1.dae"/>
      </geometry>
    </visual>
    <collision>
      <geometry>
        <mesh filename="package://rbpodo_description/meshes/rb3_730es_u/collision/link1.stl"/>
      </geometry>
    </collision>
    <inertial>
      <origin rpy="0 0 0" xyz="0.000101 -0.003241 -0.017587"/>
      <mass value="2.058"/>
      <inertia ixx="0.003" ixy="0.0" ixz="0.0" iyy="0.003" iyz="0.0" izz="0.002"/>
    </inertial>
  </link>
  <link name="link2">
    <visual>
      <geometry>
        <mesh filename="package://rbpodo_description/meshes/rb3_730es_u/visual/link2.dae"/>
      </geometry>
    </visual>
    <collision>
      <geometry>
        <mesh filename="package://rbpodo_description/meshes/rb3_730es_u/collision/link2.stl"/>
      </geometry>
    </collision>
    <inertial>
      <origin rpy="0 0 0" xyz="-0.000049 -0.095326 0.121743"/>
      <mass value="4.227"/>
      <inertia ixx="0.075" ixy="0.0" ixz="0.0" iyy="0.073" iyz="0.0" izz="0.005"/>
    </inertial>
  </link>
  <link name="link3">
    <visual>
      <geometry>
        <mesh filename="package://rbpodo_description/meshes/rb3_730es_u/visual/link3.dae"/>
      </geometry>
    </visual>
    <collision>
      <geometry>
        <mesh filename="package://rbpodo_description/meshes/rb3_730es_u/collision/link3.stl"/>
      </geometry>
    </collision>
    <inertial>
      <origin rpy="0 0 0" xyz="-0.0 -0.004 0.026"/>
      <mass value="1.45"/>
      <inertia ixx="0.002" ixy="0.0" ixz="0.0" iyy="0.002" iyz="0.0" izz="0.001"/>
    </inertial>
  </link>
  <link name="link4">
    <visual>
      <geometry>
        <mesh filename="package://rbpodo_description/meshes/rb3_730es_u/visual/link4.dae"/>
      </geometry>
    </visual>
    <collision>
      <geometry>
        <mesh filename="package://rbpodo_description/meshes/rb3_730es_u/collision/link4.stl"/>
      </geometry>
    </collision>
    <inertial>
      <origin rpy="0 0 0" xyz="0.0 -0.065 0.264"/>
      <mass value="1.798"/>
      <inertia ixx="0.02" ixy="0.0" ixz="0.0" iyy="0.018" iyz="0.004" izz="0.003"/>
    </inertial>
  </link>
  <link name="link5">
    <visual>
      <geometry>
        <mesh filename="package://rbpodo_description/meshes/rb3_730es_u/visual/link5.dae"/>
      </geometry>
    </visual>
    <collision>
      <geometry>
        <mesh filename="package://rbpodo_description/meshes/rb3_730es_u/collision/link5.stl"/>
      </geometry>
    </collision>
    <inertial>
      <origin rpy="0 0 0" xyz="0.0 -0.001 0.017"/>
      <mass value="0.944"/>
      <inertia ixx="0.000776694" ixy="5.052e-06" ixz="-5.306e-06" iyy="0.000786695" iyz="-1.7419e-05" izz="0.000515123"/>
    </inertial>
  </link>
  <link name="link6">
    <visual>
      <geometry>
        <mesh filename="package://rbpodo_description/meshes/rb3_730es_u/visual/link6.dae"/>
      </geometry>
    </visual>
    <collision>
      <geometry>
        <mesh filename="package://rbpodo_description/meshes/rb3_730es_u/collision/link6.stl"/>
      </geometry>
    </collision>
    <inertial>
      <origin rpy="0 0 0" xyz="-0.001 -0.001 0.068"/>
      <mass value="0.05"/>
      <inertia ixx="2.6302e-05" ixy="-3.4e-07" ixz="4.57e-07" iyy="1.6887e-05" iyz="1.48e-07" izz="3.5232e-05"/>
    </inertial>
  </link>
  <link name="tcp"/>
  <joint name="base" type="revolute">
    <origin rpy="0 0 0" xyz="0 0 0.1453"/>
    <parent link="link0"/>
    <child link="link1"/>
    <axis xyz="0 0 1"/>
    <limit effort="10" lower="-3.14" upper="3.14" velocity="3.14"/>
  </joint>
  <joint name="shoulder" type="revolute">
    <origin rpy="0 0 0" xyz="0 0 0"/>
    <parent link="link1"/>
    <child link="link2"/>
    <axis xyz="0 1 0"/>
    <limit effort="10" lower="-3.14" upper="3.14" velocity="3.14"/>
  </joint>
  <joint name="elbow" type="revolute">
    <origin rpy="0 0 0" xyz="0 -0.00645 0.286"/>
    <parent link="link2"/>
    <child link="link3"/>
    <axis xyz="0 1 0"/>
    <limit effort="10" lower="-3.14" upper="3.14" velocity="3.14"/>
  </joint>
  <joint name="wrist1" type="revolute">
    <origin rpy="0 0 0" xyz="0 0 0"/>
    <parent link="link3"/>
    <child link="link4"/>
    <axis xyz="0 0 1"/>
    <limit effort="10" lower="-3.14" upper="3.14" velocity="3.14"/>
  </joint>
  <joint name="wrist2" type="revolute">
    <origin rpy="0 0 0" xyz="0 0 0.344"/>
    <parent link="link4"/>
    <child link="link5"/>
    <axis xyz="0 1 0"/>
    <limit effort="10" lower="-3.14" upper="3.14" velocity="3.14"/>
  </joint>
  <joint name="wrist3" type="revolute">
    <origin rpy="0 0 0" xyz="0 0 0"/>
    <parent link="link5"/>
    <child link="link6"/>
    <axis xyz="0 0 1"/>
    <limit effort="10" lower="-3.14" upper="3.14" velocity="3.14"/>
  </joint>
  <joint name="tcp_joint" type="fixed">
    <origin rpy="0 0 0" xyz="0 0 0.1"/>
    <parent link="link6"/>
    <child link="tcp"/>
  </joint>
  <ros2_control name="RBPodoHardwareInterface" type="system">
    <hardware>
      <plugin>rbpodo_hardware/RBPodoHardwareInterface</plugin>
      <param name="cb_simulation">True</param>
      <param name="robot_ip">10.0.2.7</param>
    </hardware>
    <joint name="base">
      <param name="initial_position">0.0</param>
      <param name="torque_constant">10.100000000000001</param>
      <command_interface name="effort"/>
      <command_interface name="velocity"/>
      <command_interface name="position"/>
      <state_interface name="position"/>
      <state_interface name="effort"/>
    </joint>
    <joint name="shoulder">
      <param name="initial_position">0.0</param>
      <param name="torque_constant">10.100000000000001</param>
      <command_interface name="effort"/>
      <command_interface name="velocity"/>
      <command_interface name="position"/>
      <state_interface name="position"/>
      <state_interface name="effort"/>
    </joint>
    <joint name="elbow">
      <param name="initial_position">0.0</param>
      <param name="torque_constant">10.100000000000001</param>
      <command_interface name="effort"/>
      <command_interface name="velocity"/>
      <command_interface name="position"/>
      <state_interface name="position"/>
      <state_interface name="effort"/>
    </joint>
    <joint name="wrist1">
      <param name="initial_position">0.0</param>
      <param name="torque_constant">10.100000000000001</param>
      <command_interface name="effort"/>
      <command_interface name="velocity"/>
      <command_interface name="position"/>
      <state_interface name="position"/>
      <state_interface name="effort"/>
    </joint>
    <joint name="wrist2">
      <param name="initial_position">0.0</param>
      <param name="torque_constant">5.5</param>
      <command_interface name="effort"/>
      <command_interface name="velocity"/>
      <command_interface name="position"/>
      <state_interface name="position"/>
      <state_interface name="effort"/>
    </joint>
    <joint name="wrist3">
      <param name="initial_position">0.0</param>
      <param name="torque_constant">5.5</param>
      <command_interface name="effort"/>
      <command_interface name="velocity"/>
      <command_interface name="position"/>
      <state_interface name="position"/>
      <state_interface name="effort"/>
    </joint>
  </ros2_control>
</robot>
