<?xml version="1.0" ?>
<!-- =================================================================================== -->
<!-- |    This document was autogenerated by xacro from rb5_850e_u.urdf.xacro          | -->
<!-- |    EDITING THIS FILE BY HAND IS NOT RECOMMENDED                                 | -->
<!-- =================================================================================== -->
<robot name="rb5_850e_u">
  <link name="link0">
    <visual>
      <geometry>
        <mesh filename="package://rbpodo_description/meshes/rb5_850e_u/visual/link0.dae"/>
      </geometry>
    </visual>
    <collision>
      <geometry>
        <mesh filename="package://rbpodo_description/meshes/rb5_850e_u/collision/link0.stl"/>
      </geometry>
    </collision>
  </link>
  <link name="link1">
    <visual>
      <geometry>
        <mesh filename="package://rbpodo_description/meshes/rb5_850e_u/visual/link1.dae"/>
      </geometry>
    </visual>
    <collision>
      <geometry>
        <mesh filename="package://rbpodo_description/meshes/rb5_850e_u/collision/link1.stl"/>
      </geometry>
    </collision>
    <inertial>
      <origin rpy="0 0 0" xyz="0.000057 -0.005795 -0.034516"/>
      <mass value="4.147"/>
      <inertia ixx="0.008787118" ixy="-8.564e-06" ixz="-8.047e-06" iyy="0.008888636" iyz="0.000893025" izz="0.007845924"/>
    </inertial>
  </link>
  <link name="link2">
    <visual>
      <geometry>
        <mesh filename="package://rbpodo_description/meshes/rb5_850e_u/visual/link2.dae"/>
      </geometry>
    </visual>
    <collision>
      <geometry>
        <mesh filename="package://rbpodo_description/meshes/rb5_850e_u/collision/link2.stl"/>
      </geometry>
    </collision>
    <inertial>
      <origin rpy="0 0 0" xyz="-0.000037 -0.121603 0.212933"/>
      <mass value="9.633"/>
      <inertia ixx="0.392214367" ixy="-1.4684e-05" ixz="-5.721e-05" iyy="0.388914548" iyz="0.000255706" izz="0.021949397"/>
    </inertial>
  </link>
  <link name="link3">
    <visual>
      <geometry>
        <mesh filename="package://rbpodo_description/meshes/rb5_850e_u/visual/link3.dae"/>
      </geometry>
    </visual>
    <collision>
      <geometry>
        <mesh filename="package://rbpodo_description/meshes/rb5_850e_u/collision/link3.stl"/>
      </geometry>
    </collision>
    <inertial>
      <origin rpy="0 0 0" xyz="0.000021 -0.015845 0.202568"/>
      <mass value="3.915"/>
      <inertia ixx="0.112039835" ixy="-1.006e-06" ixz="1.4848e-05" iyy="0.111790094" iyz="0.002092668" izz="0.007569107"/>
    </inertial>
  </link>
  <link name="link4">
    <visual>
      <geometry>
        <mesh filename="package://rbpodo_description/meshes/rb5_850e_u/visual/link4.dae"/>
      </geometry>
    </visual>
    <collision>
      <geometry>
        <mesh filename="package://rbpodo_description/meshes/rb5_850e_u/collision/link4.stl"/>
      </geometry>
    </collision>
    <inertial>
      <origin rpy="0 0 0" xyz="0.000057 -0.106332 0.025881"/>
      <mass value="1.452"/>
      <inertia ixx="0.001629031" ixy="3.99e-07" ixz="2.37e-07" iyy="0.001558024" iyz="0.000127282" izz="0.001224887"/>
    </inertial>
  </link>
  <link name="link5">
    <visual>
      <geometry>
        <mesh filename="package://rbpodo_description/meshes/rb5_850e_u/visual/link5.dae"/>
      </geometry>
    </visual>
    <collision>
      <geometry>
        <mesh filename="package://rbpodo_description/meshes/rb5_850e_u/collision/link5.stl"/>
      </geometry>
    </collision>
    <inertial>
      <origin rpy="0 0 0" xyz="-0.000028 -0.025911 -0.004363"/>
      <mass value="1.454"/>
      <inertia ixx="0.001631445" ixy="1.764e-06" ixz="2.2e-07" iyy="0.001226962" iyz="0.000127473" izz="0.001560416"/>
    </inertial>
  </link>
  <link name="link6">
    <visual>
      <geometry>
        <mesh filename="package://rbpodo_description/meshes/rb5_850e_u/visual/link6.dae"/>
      </geometry>
    </visual>
    <collision>
      <geometry>
        <mesh filename="package://rbpodo_description/meshes/rb5_850e_u/collision/link6.stl"/>
      </geometry>
    </collision>
    <inertial>
      <origin rpy="0 0 0" xyz="-0.000002 -0.079964 -0.000494"/>
      <mass value="0.243"/>
      <inertia ixx="0.000147823" ixy="2.46e-07" ixz="6.43e-07" iyy="0.000243703" iyz="-5.54e-07" izz="0.000142339"/>
    </inertial>
  </link>
  <link name="tcp"/>
  <joint name="base" type="revolute">
    <origin rpy="0 0 0" xyz="0 0 0.1655"/>
    <parent link="link0"/>
    <child link="link1"/>
    <axis xyz="0 0 1"/>
    <limit effort="10" lower="-3.14" upper="3.14" velocity="3.14"/>
  </joint>
  <joint name="shoulder" type="revolute">
    <origin rpy="0 0 0" xyz="0 0 0"/>
    <parent link="link1"/>
    <child link="link2"/>
    <axis xyz="0 1 0"/>
    <limit effort="10" lower="-3.14" upper="3.14" velocity="3.14"/>
  </joint>
  <joint name="elbow" type="revolute">
    <origin rpy="0 0 0" xyz="0 0 0.425"/>
    <parent link="link2"/>
    <child link="link3"/>
    <axis xyz="0 1 0"/>
    <limit effort="10" lower="-3.14" upper="3.14" velocity="3.14"/>
  </joint>
  <joint name="wrist1" type="revolute">
    <origin rpy="0 0 0" xyz="0 0 0.392"/>
    <parent link="link3"/>
    <child link="link4"/>
    <axis xyz="0 1 0"/>
    <limit effort="10" lower="-3.14" upper="3.14" velocity="3.14"/>
  </joint>
  <joint name="wrist2" type="revolute">
    <origin rpy="0 0 0" xyz="0 -0.1107 0.1107"/>
    <parent link="link4"/>
    <child link="link5"/>
    <axis xyz="0 0 1"/>
    <limit effort="10" lower="-3.14" upper="3.14" velocity="3.14"/>
  </joint>
  <joint name="wrist3" type="revolute">
    <origin rpy="0 0 0" xyz="0 0 0"/>
    <parent link="link5"/>
    <child link="link6"/>
    <axis xyz="0 1 0"/>
    <limit effort="10" lower="-3.14" upper="3.14" velocity="3.14"/>
  </joint>
  <joint name="tcp_joint" type="fixed">
    <origin rpy="0 0 0" xyz="0 -0.0967 0"/>
    <parent link="link6"/>
    <child link="tcp"/>
  </joint>
  <ros2_control name="RBPodoHardwareInterface" type="system">
    <hardware>
      <plugin>rbpodo_hardware/RBPodoHardwareInterface</plugin>
      <param name="cb_simulation">True</param>
      <param name="robot_ip">10.0.2.7</param>
    </hardware>
    <joint name="base">
      <param name="initial_position">0.0</param>
      <param name="torque_constant">1</param>
      <command_interface name="effort"/>
      <command_interface name="velocity"/>
      <command_interface name="position"/>
      <state_interface name="position"/>
      <state_interface name="effort"/>
    </joint>
    <joint name="shoulder">
      <param name="initial_position">0.0</param>
      <param name="torque_constant">1</param>
      <command_interface name="effort"/>
      <command_interface name="velocity"/>
      <command_interface name="position"/>
      <state_interface name="position"/>
      <state_interface name="effort"/>
    </joint>
    <joint name="elbow">
      <param name="initial_position">0.0</param>
      <param name="torque_constant">1</param>
      <command_interface name="effort"/>
      <command_interface name="velocity"/>
      <command_interface name="position"/>
      <state_interface name="position"/>
      <state_interface name="effort"/>
    </joint>
    <joint name="wrist1">
      <param name="initial_position">0.0</param>
      <param name="torque_constant">1</param>
      <command_interface name="effort"/>
      <command_interface name="velocity"/>
      <command_interface name="position"/>
      <state_interface name="position"/>
      <state_interface name="effort"/>
    </joint>
    <joint name="wrist2">
      <param name="initial_position">0.0</param>
      <param name="torque_constant">1</param>
      <command_interface name="effort"/>
      <command_interface name="velocity"/>
      <command_interface name="position"/>
      <state_interface name="position"/>
      <state_interface name="effort"/>
    </joint>
    <joint name="wrist3">
      <param name="initial_position">0.0</param>
      <param name="torque_constant">1</param>
      <command_interface name="effort"/>
      <command_interface name="velocity"/>
      <command_interface name="position"/>
      <state_interface name="position"/>
      <state_interface name="effort"/>
    </joint>
  </ros2_control>
</robot>
